Workbook

Sheet 概要
B2: SAO ソードスキル一覧(原作準拠)
B4: 目的 | C4: SAW制作の参考資料として、SAO原作(旧アインクラッド編+プログレッシブ)に登場するソードスキルを武器カテゴリ別に整理したもの。
B5: 対象範囲 | C5: 旧アインクラッド編(原作1・2巻ほか)+ソードアート・オンライン プログレッシブ(1〜7巻)。ALO以降・UW初出の技も、SAO由来設定のものは参考として収録し「範囲判定」列で区別。
B6: 主な出典 | C6: 原作小説各巻、SAOプログレッシブ、マテリアル・エディション(同人設定資料)、SAO Wiki(swordartonline.fandom.com)の巻数照合。
B7: 範囲判定の凡例 | C7: 緑=旧SAO本編/プログレッシブに登場。青=プログレッシブ初出。黄=ALO以降初出(SAO由来とされる技を含む)。橙=ALO限定・UW初出・コラボ等の参考掲載。灰=設定資料のみ。
B8: ヒット数「-」 | C8: 連撃数が不明、または防御・特殊技でヒット数の概念がないもの。
B9: 注意 | C9: ヒット数・挙動は原作描写ベース。ゲーム版(ホロフラ等)の数値とは異なる場合がある。属性配分(物理◯%など)は新生ALO移植後の仕様。
B11: ゲーム出典シート | C11: 「ゲーム出典スキル」シートに、ゲーム版のソードスキルを出典明記のうえ収録。数値(SP・補正・ATK%等)は各ゲームのバランス上の仕様であり、原作設定と混同しないこと。
B12: 収録ゲーム | C12: ①ホロウ・フラグメント(PS Vita/2014、インフィニティ・モーメントの拡張移植。アインクラッド76〜100層が舞台) ②エコーズ オブ アインクラッド(2026、アインクラッド再構築。両手斧の一部は攻略情報未更新)。
B13: 原作との関係の凡例 | C13: 緑=原作にも登場(名称・概念が一致)。黄=原作技のアレンジ(ヒット数・挙動・カテゴリが原作と相違)。橙=ゲームオリジナル技。
B15: 統合一覧の並び順 | C15: 「ソードスキル一覧」は原作技とゲームオリジナル技を統合し、各カテゴリ内を推定習得可能熟練度(1〜1000)の昇順=習得順で表示。ゲームオリジナル技はスキル名を紫字、範囲判定「ゲーム出典」(紫)で区別。
B16: 習得可能熟練度の推定基準 | C16: 原作の武器スキル熟練度0〜1000の設定に準拠した独自推定値。①原作で最初に覚える技(リニアー等)=1 ②基本単発技=1〜100 ③2連撃=100〜250 ④3連撃=250〜450 ⑤4連撃・重単発=400〜600 ⑥5〜6連撃=550〜700 ⑦7〜8連撃=700〜900 ⑧9連撃以上・奥義級=850〜1000。突進・範囲・特殊効果は同格から±50調整。作中の登場時期・「上級」「最上位」等の記述を優先。ゲーム内の習得レベルは採用しない。
B17: 熟練度の注意 | C17: EXスキル(体術・刀)とユニークスキル(二刀流・神聖剣)は取得自体に特殊条件があり、数値は「そのスキル自体の熟練度」内での解禁目安。複合スキルは複数スキルの熟練度を要求する(備考参照)。
B18: 想定武器カテゴリ | C18: 「想定武器カテゴリ」シートに、原作確認済みの武器スキル全種+原作で示唆されるもの+現実の武器体系からの推定カテゴリを収録。ユニークスキル(二刀流・手裏剣術・無限槍・抜刀術・会心撃・暗黒剣・神聖剣の全10種中判明7種)は武器カテゴリとは別軸のため確度欄と備考で扱いを明記。

Sheet ソードスキル一覧
A1: 武器カテゴリ | B1: 習得可能熟練度(推定) | C1: スキル名 | D1: 英名 | E1: ヒット数 | F1: タイプ | G1: モーション・挙動 | H1: 出典 | I1: 範囲判定 | J1: 備考
A2: 片手直剣 | B2: 1 | C2: バーチカル | D2: Vertical | E2: 1 | F2: 斬(縦) | G2: 垂直に振り下ろす基本斬撃。 | H2: 8巻 / プログレッシブ3巻 | I2: 旧SAO/Prog
A3: 片手直剣 | B3: 5 | C3: ホリゾンタル | D3: Horizontal | E3: 1 | F3: 斬(横) | G3: 水平に薙ぐ基本斬撃。 | H3: 8巻 / プログレッシブ3巻 | I3: 旧SAO/Prog
A4: 片手直剣 | B4: 10 | C4: スラント | D4: Slant | E4: 1 | F4: 斬(斜) | G4: 斜めに斬り下ろす基本斬撃。 | H4: 8巻 / プログレッシブ3巻 | I4: 旧SAO/Prog
A5: 片手直剣 | B5: 20 | C5: 上段斬り(アッパーカット) | D5: Uppercut | E5: 1 | F5: 斬(斬上) | G5: 下から斬り上げる単発技。 | H5: 1巻4章 | I5: 旧SAO
A6: 片手直剣 | B6: 30 | C6: レイジ・スパイク | D6: Rage Spike | E6: 1 | F6: 突進 | G6: 敵に跳びかかり斬り上げる基本突進技。射程約10m。 | H6: 1巻 / プログレッシブ1巻 | I6: 旧SAO/Prog | J6: 威力は低め。
A7: 片手直剣 | B7: 50 | C7: ソニック・リープ | D7: Sonic Leap | E7: 1 | F7: 突進 | G7: 突進して打ち下ろす突進斬撃。 | H7: プログレッシブ3巻 | I7: 旧SAO/Prog
A8: 片手直剣 | B8: 60 | C8: ブレイクリフター | D8: - | E8: 1 | F8: 突 | G8: 素早い刺突+ノックバック。 | H8: ゲーム(EoA) | I8: ゲーム出典
A9: 片手直剣 | B9: 80 | C9: バーチカル・アーク | D9: Vertical Arc | E9: 2 | F9: 斬 | G9: V字の軌道を描く二連撃。 | H9: プログレッシブ1巻 / 10巻 | I9: 旧SAO/Prog
A10: 片手直剣 | B10: 100 | C10: ホリゾンタル・アーク | D10: Horizontal Arc | E10: 2 | F10: 斬 | G10: 左→右、返しで右→左の水平二連撃。 | H10: プログレッシブ2巻 | I10: Prog
A11: 片手直剣 | B11: 120 | C11: セレーション・ウェーブ | D11: Serration Wave | E11: 1 | F11: 範囲 | G11: 移動阻害目的の単発AOE。ダメージ極小。 | H11: The Day Before(外伝) | I11: 旧SAO
A12: 片手直剣 | B12: 180 | C12: スネーク・バイト | D12: Snake Bite | E12: 2 | F12: 斬 | G12: 左右連続の振りで相手の武器を狙う。確率で武器破壊。 | H12: 10巻 | I12: ALO以降初出
A13: 片手直剣 | B13: 200 | C13: レイジインパクト | D13: - | E13: 1 | F13: 斬 | G13: 素早い突進からの中範囲強斬撃。 | H13: ゲーム(EoA) | I13: ゲーム出典
A14: 片手直剣 | B14: 250 | C14: シャープ・ネイル | D14: Sharp Nail | E14: 3 | F14: 斬 | G14: 斜め斬上→水平→斜め斬下の三連撃。 | H14: プログレッシブ2巻・3巻 | I14: Prog
A15: 片手直剣 | B15: 300 | C15: サベージ・フルクラム | D15: Savage Fulcrum | E15: 3 | F15: 斬 | G15: 数字の「4」を描く軌道の三連撃。 | H15: 8巻 | I15: ALO以降初出
A16: 片手直剣 | B16: 400 | C16: バーチカル・スクエア | D16: Vertical Square | E16: 4 | F16: 斬 | G16: 正方形の軌道を描く中級四連撃。 | H16: 1巻9章 | I16: 旧SAO
A17: 片手直剣 | B17: 420 | C17: ホリゾンタル・スクエア | D17: Horizontal Square | E17: 4 | F17: 斬 | G17: 菱形の軌道を描く中級四連撃。 | H17: プログレッシブ3巻 | I17: 旧SAO/Prog
A18: 片手直剣 | B18: 550 | C18: ヴォーパル・ストライク | D18: Vorpal Strike | E18: 1 | F18: 突 | G18: 刃渡り2倍リーチの高威力重突き。クールタイム長。 | H18: 2巻 | I18: 旧SAO
A19: 片手直剣 | B19: 650 | C19: スター・Q・プロミネンス | D19: - | E19: 6 | F19: 突 | G19: 六連突き(ダブルATK)。 | H19: ゲーム(HF) | I19: ゲーム出典
A20: 片手直剣 | B20: 700 | C20: カーネージ・アライアンス | D20: - | E20: 6 | F20: 斬 | G20: 六連撃+PT支援効果。 | H20: ゲーム(HF) | I20: ゲーム出典 | J20: 実装エレメント調査で解放。
A21: 片手直剣 | B21: 750 | C21: デッドリー・シンズ | D21: Deadly Sins | E21: 7 | F21: 斬 | G21: 多様な斬撃+全周回転+後方宙返りの七連撃。 | H21: 7巻 | I21: ALO以降初出
A22: 片手直剣 | B22: 800 | C22: ハウリング・オクターブ | D22: Howling Octave | E22: 8 | F22: 突+斬 | G22: 高速五連突き→斬下→斬上→全力打ち下ろしの八連撃。 | H22: 8巻 | I22: 旧SAO由来(初出はALO)
A23: 片手直剣 | B23: 850 | C23: ライトニング・フォール | D23: Lightning Fall | E23: 1 | F23: 範囲 | G23: 跳躍から剣を地面へ突き立て全方位に電撃を放つ重範囲技。 | H23: 8巻 | I23: ALO限定 | J23: 参考掲載。
A24: 片手直剣 | B24: 900 | C24: ファントム・レイブ | D24: - | E24: 6 | F24: 斬 | G24: 高速六連撃の奥義級スキル。 | H24: ゲーム(HF) | I24: ゲーム出典
A25: 片手直剣 | B25: 950 | C25: ノヴァ・アセンション | D25: Nova Ascension | E25: 10 | F25: 連撃 | G25: 片手直剣カテゴリ最上位級の十連撃。 | H25: 14巻 | I25: UW初出 | J25: 参考掲載。
A26: 曲刀 | B26: 10 | C26: リーバー | D26: Reaver | E26: 1 | F26: 斬 | G26: 曲刀の基本単発技。 | H26: 1巻2章 | I26: 旧SAO
A27: 曲刀 | B27: 150 | C27: デス・クリープ | D27: - | E27: 1 | F27: 斬 | G27: 高威力の単発範囲斬撃。 | H27: ゲーム(HF) | I27: ゲーム出典
A28: 曲刀 | B28: 300 | C28: フェル・クレセント | D28: Fell Crescent | E28: 1 | F28: 突進 | G28: 0.4秒で4mを踏み込み打ち下ろす上級突進技。 | H28: 1巻(アリア) | I28: 旧SAO/Prog
A29: 曲刀 | B29: 350 | C29: オーバル・クレセント | D29: - | E29: 3 | F29: 斬 | G29: 楕円軌道の三連範囲斬撃。 | H29: ゲーム(HF) | I29: ゲーム出典
A30: 曲刀 | B30: 450 | C30: ファラント・フルムーン | D30: - | E30: 4 | F30: 斬 | G30: 円月軌道の四連撃。 | H30: ゲーム(HF) | I30: ゲーム出典
A31: 曲刀 | B31: 500 | C31: レイジング・チョッパー | D31: - | E31: 4 | F31: 斬 | G31: 高命中の四連斬撃。 | H31: ゲーム(HF) | I31: ゲーム出典
A32: 曲刀 | B32: 550 | C32: ミリー・スラッシュ | D32: - | E32: 4 | F32: 斬 | G32: 重い四連斬撃。 | H32: ゲーム(HF) | I32: ゲーム出典
A33: 曲刀 | B33: 600 | C33: ベア・ノック | D33: - | E33: 4 | F33: 打 | G33: 範囲を薙ぐ重打撃四連。 | H33: ゲーム(HF) | I33: ゲーム出典
A34: 曲刀 | B34: 650 | C34: ダンシング・ヘルレイザー | D34: - | E34: 4 | F34: 斬 | G34: 舞うような高速四連撃。 | H34: ゲーム(HF) | I34: ゲーム出典
A35: 曲刀 | B35: 700 | C35: スラッシング・レイ | D35: Slashing Ray | E35: - | F35: 斬 | G35: 曲刀の上級技。詳細描写少。 | H35: プログレッシブ7巻 | I35: Prog
A36: 曲刀 | B36: 750 | C36: マーサクル・リッパー | D36: - | E36: 4 | F36: 斬 | G36: リスク低減効果を持つ四連撃。 | H36: ゲーム(HF) | I36: ゲーム出典 | J36: 実装エレメント調査で解放。
A37: 曲刀 | B37: 950 | C37: レギオン・デストロイヤー | D37: - | E37: 7 | F37: 斬 | G37: 七連撃の奥義級スキル。 | H37: ゲーム(HF) | I37: ゲーム出典
A38: 短剣 | B38: 10 | C38: ウィップスナップ | D38: - | E38: 1 | F38: 斬 | G38: 後退しながらの斬撃。 | H38: ゲーム(EoA) | I38: ゲーム出典
A39: 短剣 | B39: 150 | C39: ケイナイン | D39: Canine | E39: 1 | F39: 突 | G39: 斬り上げるような上方向への突き。 | H39: 21巻 | I39: UW初出 | J39: 参考掲載。
A40: 短剣 | B40: 180 | C40: サイド・バイト | D40: - | E40: 2 | F40: 斬 | G40: 左右からの二連撃。 | H40: ゲーム(HF) | I40: ゲーム出典
...

Sheet カテゴリ別サマリ
A1: 武器カテゴリ | B1: 収録数 | C1: うちゲーム出典
A2: 片手直剣 | B2: =COUNTIF(ソードスキル一覧!$A$2:$A$186,A2) -> 24 | C2: =COUNTIFS(ソードスキル一覧!$A$2:$A$186,A2,ソードスキル一覧!$I$2:$I$186,"ゲーム出典") -> 5
A3: 曲刀 | B3: =COUNTIF(ソードスキル一覧!$A$2:$A$186,A3) -> 12 | C3: =COUNTIFS(ソードスキル一覧!$A$2:$A$186,A3,ソードスキル一覧!$I$2:$I$186,"ゲーム出典") -> 9
A4: 短剣 | B4: =COUNTIF(ソードスキル一覧!$A$2:$A$186,A4) -> 18 | C4: =COUNTIFS(ソードスキル一覧!$A$2:$A$186,A4,ソードスキル一覧!$I$2:$I$186,"ゲーム出典") -> 15
A5: 細剣 | B5: =COUNTIF(ソードスキル一覧!$A$2:$A$186,A5) -> 25 | C5: =COUNTIFS(ソードスキル一覧!$A$2:$A$186,A5,ソードスキル一覧!$I$2:$I$186,"ゲーム出典") -> 12
A6: 両手剣 | B6: =COUNTIF(ソードスキル一覧!$A$2:$A$186,A6) -> 19 | C6: =COUNTIFS(ソードスキル一覧!$A$2:$A$186,A6,ソードスキル一覧!$I$2:$I$186,"ゲーム出典") -> 14
A7: 片手斧 | B7: =COUNTIF(ソードスキル一覧!$A$2:$A$186,A7) -> 1 | C7: =COUNTIFS(ソードスキル一覧!$A$2:$A$186,A7,ソードスキル一覧!$I$2:$I$186,"ゲーム出典") -> 0
A8: 両手斧 | B8: =COUNTIF(ソードスキル一覧!$A$2:$A$186,A8) -> 19 | C8: =COUNTIFS(ソードスキル一覧!$A$2:$A$186,A8,ソードスキル一覧!$I$2:$I$186,"ゲーム出典") -> 18
A9: 片手棍 | B9: =COUNTIF(ソードスキル一覧!$A$2:$A$186,A9) -> 20 | C9: =COUNTIFS(ソードスキル一覧!$A$2:$A$186,A9,ソードスキル一覧!$I$2:$I$186,"ゲーム出典") -> 20
A10: 槍 | B10: =COUNTIF(ソードスキル一覧!$A$2:$A$186,A10) -> 11 | C10: =COUNTIFS(ソードスキル一覧!$A$2:$A$186,A10,ソードスキル一覧!$I$2:$I$186,"ゲーム出典") -> 10
A11: 投剣 | B11: =COUNTIF(ソードスキル一覧!$A$2:$A$186,A11) -> 1 | C11: =COUNTIFS(ソードスキル一覧!$A$2:$A$186,A11,ソードスキル一覧!$I$2:$I$186,"ゲーム出典") -> 0
A12: 体術(EX) | B12: =COUNTIF(ソードスキル一覧!$A$2:$A$186,A12) -> 5 | C12: =COUNTIFS(ソードスキル一覧!$A$2:$A$186,A12,ソードスキル一覧!$I$2:$I$186,"ゲーム出典") -> 0
A13: 刀(EX) | B13: =COUNTIF(ソードスキル一覧!$A$2:$A$186,A13) -> 12 | C13: =COUNTIFS(ソードスキル一覧!$A$2:$A$186,A13,ソードスキル一覧!$I$2:$I$186,"ゲーム出典") -> 5
... A17: 複合(片手剣+体術) | B17: =COUNTIF(ソードスキル一覧!$A$2:$A$186,A17) -> 2 | C17: =COUNTIFS(ソードスキル一覧!$A$2:$A$186,A17,ソードスキル一覧!$I$2:$I$186,"ゲーム出典") -> 0
A18: 合計 | B18: =SUM(B2:B17) -> 185 | C18: =SUM(C2:C17) -> 118

Sheet 想定武器カテゴリ
A1: 凡例: ◎=原作で武器スキルとして確認 / ◯=原作で装備・使用が示唆 / △=推定(蓋然性高) / ▲=推定(要検討) / ✕=非実装が示唆
A2: 区分 | B2: カテゴリ名 | C2: 想定される現実の武器例 | D2: 確度 | E2: 根拠 | F2: タイプ傾向 | G2: SAW設計メモ
A3: 片手武器 | B3: 片手用直剣 | C3: ロングソード、ブロードソード、グラディウス、スパタ | D3: ◎ | E3: キリトの主武器。武器スキルとして明言。 | F3: 斬・突 | G3: 基準カテゴリ。細剣・両手剣の解禁前提スキル。
A4: 片手武器 | B4: 細剣 | C4: レイピア、エストック、スモールソード | D4: ◎ | E4: アスナの主武器。片手直剣の熟練で出現。 | F4: 突 | G4: 突き特化。エストックなら突き技のみ流用可(原作言及)。
A5: 片手武器 | B5: 片手用曲刀 | C5: シミター、サーベル、カットラス、ファルシオン、ダオ | D5: ◎ | E5: 武器スキルとして明言。熟練で刀が出現。 | F5: 斬 | G5: 斬撃特化。刀への中継カテゴリ。
A6: 片手武器 | B6: 短剣 | C6: ダガー、ナイフ、ダーク、クリス、タントー | D6: ◎ | E6: 武器スキルとして明言。 | F6: 突・斬 | G6: 手数・隠密系と好相性。
A7: 片手武器 | B7: 鎧通し | C7: スティレット、メイルブレイカー、パンツァーシュテッヒャー | D7: ◎ | E7: 武器スキル「鎧通し(アーマーピアーズ)」として設定資料に記載。 | F7: 突 | G7: 防御無視・急所特化のニッチカテゴリ。
A8: 片手武器 | B8: 片手棍 | C8: メイス、ウォーハンマー(片手)、モーニングスター | D8: ◎ | E8: 武器スキル「片手棍(片手用戦槌)」として明言。 | F8: 打 | G8: スタン・体勢崩し特化。
A9: 片手武器 | B9: 片手斧 | C9: ハンドアックス、トマホーク | D9: ◎ | E9: 武器スキルとして明言。ダブル・クリーブが原作登場。 | F9: 斬 | G9: 重斬撃。投斧との複合の余地。
A10: 片手武器 | B10: 片手槍 | C10: ショートスピア | D10: ◎ | E10: 武器スキルとして設定資料に記載。 | F10: 突 | G10: 盾との併用前提の中リーチ。
A11: 片手武器 | B11: 片手突撃槍 | C11: ランス(片手)、カヴァルリーランス | D11: ◎ | E11: 武器スキルとして設定資料に記載。 | F11: 突 | G11: 突進技特化。移動速度依存の威力補正が似合う。
A12: 片手武器 | B12: 爪 | C12: クロー、バグナウ、鉄爪 | D12: ◎ | E12: 武器スキル「爪」として設定資料に記載。 | F12: 斬 | G12: 連撃・出血特化。体術との複合候補。
A13: 両手武器 | B13: 両手用直剣 | C13: ツーハンデッドソード、クレイモア、ツヴァイヘンダー | D13: ◎ | E13: 武器スキルとして明言。片手直剣の熟練で出現。 | F13: 斬 | G13: 高威力・高硬直。
... A46: 参考(非実装) | B46: 銃・火器 | C46: マスケット等 | D46: ✕ | E46: 世界観外(GGOの領分)。 | F46: 射撃 | G46: 収録外。比較参照用。
A48: 確度別集計
A49: ◎ | B49: =COUNTIF($D$3:$D$46,"◎") -> 19
A50: ◯ | B50: =COUNTIF($D$3:$D$46,"◯") -> 4
A51: △ | B51: =COUNTIF($D$3:$D$46,"△") -> 10
A52: ▲ | B52: =COUNTIF($D$3:$D$46,"▲") -> 8
A53: ✕ | B53: =COUNTIF($D$3:$D$46,"✕") -> 3
A54: 合計 | B54: =SUM(B49:B53) -> 44

Sheet ゲーム出典スキル
A1: 出典ゲーム | B1: 武器カテゴリ | C1: スキル名 | D1: 属性 | E1: ヒット数 | F1: 消費SP | G1: 効果・挙動 | H1: 原作との関係 | I1: 備考
A2: ホロウ・フラグメント(2014/Vita) | B2: 短剣 | C2: アーマー・ピアス | D2: 突 | E2: 1 | F2: 100 | G2: DEX50%補正。高命中、防御力DW付与。 | H2: ゲームオリジナル | I2: 名称は原作の武器スキル「鎧通し」由来。
A3: ホロウ・フラグメント(2014/Vita) | B3: 短剣 | C3: サイド・バイト | D3: 斬 | E3: 2 | F3: 100 | G3: DEX40%+AGI40%補正。稀に束縛付与。 | H3: ゲームオリジナル
A4: ホロウ・フラグメント(2014/Vita) | B4: 短剣 | C4: ラウンド・アクセル | D4: 斬 | E4: 2 | F4: 100 | G4: STR40%+DEX50%補正。高命中の範囲技。 | H4: ゲームオリジナル
A5: ホロウ・フラグメント(2014/Vita) | B5: 短剣 | C5: クロス・エッジ | D5: 斬 | E5: 2 | F5: 100 | G5: DEX100%補正。高命中、DEX低下付与。 | H5: ゲームオリジナル
A6: ホロウ・フラグメント(2014/Vita) | B6: 短剣 | C6: ラピッド・バイト | D6: 突 | E6: 2 | F6: 100 | G6: DEX110%補正。高命中、VIT低下付与。 | H6: 原作技のアレンジ | I6: 原作では1ヒットの中級突進技。
A7: ホロウ・フラグメント(2014/Vita) | B7: 短剣 | C7: トライ・ピアース | D7: 突 | E7: 3 | F7: 100 | G7: DEX120%補正。高命中、AGI低下付与。 | H7: ゲームオリジナル
A8: ホロウ・フラグメント(2014/Vita) | B8: 短剣 | C8: ファッド・エッジ | D8: 突 | E8: 4 | F8: 100 | G8: DEX90%+AGI20%補正。高命中、出血付与。 | H8: 原作技のアレンジ | I8: 原作では詳細不明の技を4連撃として具体化。
A9: ホロウ・フラグメント(2014/Vita) | B9: 短剣 | C9: インフィニット | D9: 突 | E9: 5 | F9: 100 | G9: AGI90%補正。高命中の重攻撃技、STR低下付与。 | H9: ゲームオリジナル
A10: ホロウ・フラグメント(2014/Vita) | B10: 短剣 | C10: シャドウ・ステッチ | D10: 打 | E10: 3 | F10: 100 | G10: STR40%+DEX80%補正。高命中、麻痺付与。 | H10: ゲームオリジナル
A11: ホロウ・フラグメント(2014/Vita) | B11: 短剣 | C11: アクセル・レイド | D11: 斬 | E11: 9 | F11: 100 | G11: AGI80%+VIT50%補正。超高命中、命中DW付与。 | H11: ゲームオリジナル | I11: HF新規スキル。
A12: ホロウ・フラグメント(2014/Vita) | B12: 短剣 | C12: グラヴィティマグナム | D12: 突 | E12: 4 | F12: 100 | G12: DEX140%補正。背面攻撃量増加、自身防御DW。 | H12: ゲームオリジナル | I12: 実装エレメント調査で解放。
A13: ホロウ・フラグメント(2014/Vita) | B13: 短剣 | C13: エターナル・サイクロン | D13: 突 | E13: 4 | F13: 150 | G13: DEX120%+AGI50%補正。奥義技。 | H13: ゲームオリジナル
A14: ホロウ・フラグメント(2014/Vita) | B14: 片手剣 | C14: ソニック・リープ | D14: 斬 | E14: 1 | F14: 100 | G14: AGI40%補正。稀に束縛付与。 | H14: 原作にも登場
A15: ホロウ・フラグメント(2014/Vita) | B15: 片手剣 | C15: ヴォーパル・ストライク | D15: 突 | E15: 3 | F15: 100 | G15: STR30%+AGI30%補正。高命中の範囲技。 | H15: 原作技のアレンジ | I15: 原作では1ヒットの重突き。
A16: ホロウ・フラグメント(2014/Vita) | B16: 片手剣 | C16: スラント | D16: 斬 | E16: 1 | F16: 100 | G16: STR40%+AGI40%補正。暗闇Lv2付与。 | H16: 原作にも登場
A17: ホロウ・フラグメント(2014/Vita) | B17: 片手剣 | C17: ホリゾンタル | D17: 斬 | E17: 1 | F17: 100 | G17: STR40%+DEX40%補正。範囲技、稀に束縛付与。 | H17: 原作にも登場
A18: ホロウ・フラグメント(2014/Vita) | B18: 片手剣 | C18: バーチカル | D18: 斬 | E18: 1 | F18: 100 | G18: STR40%+VIT40%補正。高命中、低スタン。 | H18: 原作にも登場
A19: ホロウ・フラグメント(2014/Vita) | B19: 片手剣 | C19: スター・Q・プロミネンス | D19: 突 | E19: 6 | F19: 100 | G19: STR40%+DEX30%補正。ダブルATK。 | H19: ゲームオリジナル
A20: ホロウ・フラグメント(2014/Vita) | B20: 片手剣 | C20: ホリゾンタル・スクエア | D20: 斬 | E20: 4 | F20: 100 | G20: 全ステータス30%補正。高命中、防御力DW付与。 | H20: 原作にも登場
A21: ホロウ・フラグメント(2014/Vita) | B21: 片手剣 | C21: バーチカル・スクエア | D21: 斬 | E21: 4 | F21: 100 | G21: STR30%+DEX50%補正。高麻痺付与。 | H21: 原作にも登場
A22: ホロウ・フラグメント(2014/Vita) | B22: 片手剣 | C22: サベージ・フルクラム | D22: 斬 | E22: 4 | F22: 100 | G22: 全ステータス60%補正。攻撃&防御力DW。 | H22: 原作技のアレンジ | I22: HF新規。原作(ALO)では3連撃。
A23: ホロウ・フラグメント(2014/Vita) | B23: 片手剣 | C23: メテオ・ブレイク | D23: 打 | E23: 3 | F23: 100 | G23: STR50%+VIT40%補正。重攻撃技。 | H23: 原作技のアレンジ | I23: 原作では体術との複合7連撃。
A24: ホロウ・フラグメント(2014/Vita) | B24: 片手剣 | C24: カーネージ・アライアンス | D24: 斬 | E24: 6 | F24: 100 | G24: VIT120%補正。PT攻撃&被ダメカット付与、BST&SP減。 | H24: ゲームオリジナル | I24: 実装エレメント調査で解放。
A25: ホロウ・フラグメント(2014/Vita) | B25: 片手剣 | C25: ファントム・レイブ | D25: 斬 | E25: 6 | F25: 150 | G25: DEX130%+AGI120%補正。奥義技。 | H25: ゲームオリジナル
A26: ホロウ・フラグメント(2014/Vita) | B26: 曲刀 | C26: フェル・クレセント | D26: 斬 | E26: 1 | F26: 100 | G26: STR50%補正。高命中の範囲技、稀に束縛付与。 | H26: 原作にも登場
A27: ホロウ・フラグメント(2014/Vita) | B27: 曲刀 | C27: リーバー | D27: 斬 | E27: 2 | F27: 100 | G27: STR60%補正。範囲技、出血付与。 | H27: 原作技のアレンジ | I27: 原作では1ヒットの基本技。
A28: ホロウ・フラグメント(2014/Vita) | B28: 曲刀 | C28: ファラント・フルムーン | D28: 斬 | E28: 4 | F28: 100 | G28: STR70%補正。低スタン。 | H28: ゲームオリジナル
A29: ホロウ・フラグメント(2014/Vita) | B29: 曲刀 | C29: ベア・ノック | D29: 打 | E29: 4 | F29: 100 | G29: STR50%+AGI30%補正。範囲重攻撃技。 | H29: ゲームオリジナル
A30: ホロウ・フラグメント(2014/Vita) | B30: 曲刀 | C30: オーバル・クレセント | D30: 斬 | E30: 3 | F30: 100 | G30: 全ステータス30%補正。範囲技。 | H30: ゲームオリジナル
A31: ホロウ・フラグメント(2014/Vita) | B31: 曲刀 | C31: デス・クリープ | D31: 斬 | E31: 1 | F31: 100 | G31: STR80%補正。範囲技、回避DW付与。 | H31: ゲームオリジナル
A32: ホロウ・フラグメント(2014/Vita) | B32: 曲刀 | C32: レイジング・チョッパー | D32: 斬 | E32: 4 | F32: 100 | G32: STR50%+VIT40%補正。高命中。 | H32: ゲームオリジナル
A33: ホロウ・フラグメント(2014/Vita) | B33: 曲刀 | C33: ミリー・スラッシュ | D33: 斬 | E33: 4 | F33: 100 | G33: STR50%+AGI50%補正。重攻撃技。 | H33: ゲームオリジナル
A34: ホロウ・フラグメント(2014/Vita) | B34: 曲刀 | C34: ダンシング・ヘルレイザー | D34: 斬 | E34: 4 | F34: 100 | G34: DEX60%+AGI60%補正。高命中、防御力DW付与。 | H34: ゲームオリジナル | I34: HF新規スキル。
A35: ホロウ・フラグメント(2014/Vita) | B35: 曲刀 | C35: マーサクル・リッパー | D35: 斬 | E35: 4 | F35: 100 | G35: STR60%+VIT60%補正。自身リスク低減効果。 | H35: ゲームオリジナル | I35: 実装エレメント調査で解放。
A36: ホロウ・フラグメント(2014/Vita) | B36: 曲刀 | C36: レギオン・デストロイヤー | D36: 斬 | E36: 7 | F36: 150 | G36: STR70%+VIT70%補正。奥義技、出血付与。 | H36: ゲームオリジナル
A37: ホロウ・フラグメント(2014/Vita) | B37: 細剣 | C37: リニアー | D37: 突 | E37: 1 | F37: 100 | G37: DEX50%補正。範囲技、稀に束縛付与。 | H37: 原作にも登場
A38: ホロウ・フラグメント(2014/Vita) | B38: 細剣 | C38: ストリーク | D38: 斬 | E38: 1 | F38: 100 | G38: DEX30%+AGI30%補正。高命中の範囲技。 | H38: 原作にも登場
A39: ホロウ・フラグメント(2014/Vita) | B39: 細剣 | C39: アヴォーヴ | D39: 斬 | E39: 1 | F39: 100 | G39: DEX20%+AGI40%補正。低スタン。 | H39: ゲームオリジナル | I39: 前作インフィニティ・モーメント由来。
A40: ホロウ・フラグメント(2014/Vita) | B40: 細剣 | C40: オーバーラジェーション | D40: 突 | E40: 10 | F40: 100 | G40: DEX30%+AGI30%補正。重攻撃技。 | H40: ゲームオリジナル | I40: 前作インフィニティ・モーメント由来。
...
